Workbook

Sheet Tổng quan
A1: KẾ HOẠCH ĐỒ ÁN: INVENTORY MICROSERVICE (tên tạm)
A2: Dựa trên SRS TigerNet v1.1 · lập ngày 25/10/2026 · các ô nền vàng là ô cần điền/cập nhật
A4: Tên dự án | B4: (chưa đặt tên) – Hệ thống quản lý kho đa kho, kiến trúc microservice
A5: Nguồn yêu cầu | B5: SRS TigerNet v1.1 (Google Drive) – mục 3 chức năng, mục 6 dữ liệu, mục 8.5 kịch bản đa kho
A6: Thời gian | B6: 2 tháng: 26/10/2026 → 25/12/2026 (8 tuần phát triển + 1 tuần kiểm thử, bàn giao)
A7: Nhân sự | B7: 3 người: Nhật (Backend 1), Quân (Backend 2), Nghĩa (Frontend + UI/UX Figma)
A8: Backend | B8: NodeJS 22 · Express · Prisma · MySQL 8 (database per service) · Redis · RabbitMQ · Socket.IO · Jest
A9: Frontend | B9: React 18 · Vite · Ant Design 5 · React Router · TanStack Query · Zustand · Recharts · Vitest
A10: Thiết kế | B10: Figma: sitemap, user flow, wireframe, design system (light/dark), hi-fi desktop + mobile, prototype
A11: Hạ tầng | B11: Docker Compose (dev + demo) · GitHub Actions CI · deploy VPS/Render khi bàn giao
A12: Services | B12: api-gateway · auth-service · catalog-service · inventory-service · order-service · report-service
A13: Phạm vi KHÔNG làm | B13: App Flutter, offline mode, đăng nhập Google OAuth, xuất .doc/.xml; vị trí Khu-Kệ-Ô là stretch goal
A14: Tài liệu kèm | B14: Thiet_ke_he_thong.md · database/schema.sql · diagrams/*.png (kiến trúc, ERD 5 service, luồng xuất kho, git workflow)
A16: THÀNH VIÊN
A17: Thành viên | B17: Họ tên | C17: Vai trò | D17: Phụ trách chính | E17: Review chéo
A18: Nhật | B18: Nhật | C18: Backend 1 + DevOps | D18: packages/common, api-gateway, auth-service, catalog-service, report-service (báo cáo, cảnh báo, audit, xuất file, backup), thanh toán/công nợ, CI/CD, deploy | E18: PR của Quân
A19: Quân | B19: Quân | C19: Backend 2 + Database | D19: Thiết kế CSDL, docker-compose, inventory-service (kho, tồn, serial, giữ hàng, kiểm kê), order-service (nhập, xuất, chuyển kho, thuê/mượn, đổi trả), test kịch bản 8.5 | E19: PR của Nhật
A20: Nghĩa | B20: Nghĩa | C20: Frontend + UI/UX (Figma) | D20: Figma (toàn bộ), React Vite app, tích hợp API, responsive, dark mode | E20: Nhật/Quân review phần gọi API
A22: CỘT MỐC
A23: Sprint | B23: Thời gian | C23: Mục tiêu | D23: Release | E23: Demo
A24: Sprint 1 (W1–W2) | B24: 26/10 – 08/11 | C24: Nền tảng: repo, docker, CSDL, common lib, gateway, đăng nhập, kho; Figma design system + wireframe; FE khung app | D24: v0.1.0 | E24: 08/11
A25: Sprint 2 (W3–W4) | B25: 09/11 – 22/11 | C25: Danh mục, người dùng & phân quyền kho, lõi tồn kho, phiếu nhập; Figma hi-fi hoàn tất; FE đăng nhập + danh mục | D25: v0.2.0 | E25: 22/11
A26: Sprint 3 (W5–W6) | B26: 23/11 – 06/12 | C26: Phiếu xuất, giữ hàng, chuyển kho, thanh toán/công nợ, cảnh báo, event báo cáo; FE nhập/xuất/kho | D26: v0.3.0 | E26: 06/12
A27: Sprint 4 (W7–W8) | B27: 07/12 – 20/12 | C27: Thuê/mượn, đổi trả, kiểm kê, báo cáo + xuất file, backup; FE toàn bộ màn còn lại; code freeze 20/12 | D27: v0.4.0 | E27: 20/12
A28: Bàn giao (W9) | B28: 21/12 – 25/12 | C28: UAT theo SRS mục 8, sửa lỗi, deploy, tài liệu, slide, video demo | D28: v1.0.0 | E28: 25/12
A30: RỦI RO
A31: Rủi ro | B31: Ảnh hưởng | C31: Cách xử lý
A32: Order-service nhiều nghiệp vụ, Quân quá tải | B32: Trễ Sprint 3–4 | C32: Nhật nhận thanh toán/công nợ/bảo hành; nếu trễ cắt vị trí Khu-Kệ-Ô và giảm báo cáo đa kho xuống 1 màn so sánh
A33: Nghĩa vừa Figma vừa code | B33: Màn hình code trễ | C33: Figma hi-fi xong trước W4; dùng Ant Design để giảm tự code component; Nhật hỗ trợ màn admin ở W8
A34: Sai lệch tồn khi đồng thời | B34: Fail kịch bản 8.5#5 | C34: Transaction + SELECT FOR UPDATE + version + Redis lock; viết test đồng thời từ W4
A35: Đổi API giữa chừng | B35: FE phải sửa nhiều | C35: Chốt OpenAPI W2; đổi contract phải có FE approve PR; dùng mock (MSW) khi BE chưa xong
A36: Microservice khó debug | B36: Mất thời gian | C36: Log có request-id xuyên service (pino), docker compose 1 lệnh, health check mỗi service

Sheet Kế hoạch & Chia việc
A1: KẾ HOẠCH 9 TUẦN & CHIA VIỆC
A2: Tuần BĐ/KT nhập số 1–9 (W1 = 26/10/2026). Biểu đồ Gantt tự tô màu theo Tuần BĐ–KT. Cột Trạng thái chọn từ danh sách.
L3: Số tuần → | M3: 1 | N3: 2 | O3: 3 | P3: 4 | Q3: 5 | R3: 6 | S3: 7 | T3: 8 | U3: 9
A4: ID | B4: Sprint | C4: Hạng mục | D4: Công việc | E4: Người | F4: Tuần BĐ | G4: Tuần KT | H4: Giờ ước tính | I4: Ưu tiên | J4: Phụ thuộc | K4: Kết quả bàn giao | L4: Trạng thái | M4: W1 26/10–01/11 | N4: W2 02/11–08/11 | O4: W3 09/11–15/11 | P4: W4 16/11–22/11 | Q4: W5 23/11–29/11 | R4: W6 30/11–06/12 | S4: W7 07/12–13/12 | T4: W8 14/12–20/12 | U4: W9 21/12–25/12
A5: T01 | B5: Sprint 1 | C5: Quản lý | D5: Kick-off, đọc SRS v1.1, chốt phạm vi MVP, tạo GitHub Project & issue từ sheet này | E5: Cả nhóm | F5: 1 | G5: 1 | H5: 4 | I5: P0 | K5: Backlog trên GitHub Projects | L5: Chưa bắt đầu
A6: T02 | B6: Sprint 1 | C6: DevOps | D6: Tạo monorepo (npm workspaces), ESLint/Prettier, husky + commitlint, PR template, CODEOWNERS, branch protection | E6: Nhật | F6: 1 | G6: 1 | H6: 6 | I6: P0 | K6: Repo + quy ước | L6: Chưa bắt đầu
A7: T03 | B7: Sprint 1 | C7: Database | D7: Review & chốt ERD + schema.sql 5 database; Prisma schema + migration + seed cho từng service | E7: Quân | F7: 1 | G7: 1 | H7: 10 | I7: P0 | K7: schema.prisma ×5, seed | L7: Chưa bắt đầu
A8: T04 | B8: Sprint 1 | C8: DevOps | D8: docker-compose: MySQL, Redis, RabbitMQ, MailHog + init SQL; .env.example | E8: Quân | F8: 1 | G8: 1 | H8: 5 | I8: P0 | K8: docker compose up chạy được | L8: Chưa bắt đầu
A9: T05 | B9: Sprint 1 | C9: Backend chung | D9: packages/common: logger(pino, request-id), AppError, errorHandler, response, validate(zod), auth-context, requireRole, requireWarehouseAccess, rabbitmq, httpClient, idempotency | E9: Nhật | F9: 1 | G9: 2 | H9: 12 | I9: P0 | K9: @inv/common | L9: Chưa bắt đầu
A10: T06 | B10: Sprint 1 | C10: API contract | D10: Chốt OpenAPI v1 cho toàn bộ endpoint (sheet API), mock server cho FE | E10: Cả nhóm | F10: 1 | G10: 2 | H10: 8 | I10: P0 | K10: docs/openapi/*.yaml | L10: Chưa bắt đầu
A11: T07 | B11: Sprint 1 | C11: DevOps | D11: GitHub Actions CI: lint + test + build theo service (paths filter) | E11: Nhật | F11: 1 | G11: 1 | H11: 4 | I11: P0 | K11: ci.yml xanh | L11: Chưa bắt đầu
A12: T08 | B12: Sprint 1 | C12: Gateway | D12: api-gateway: proxy 5 service, verify JWT, gắn header user/kho, rate limit theo user/ngày, CORS, gộp Swagger, proxy WebSocket | E12: Nhật | F12: 2 | G12: 2 | H12: 8 | I12: P0 | J12: common | K12: Gateway :8080 | L12: Chưa bắt đầu
A13: T09 | B13: Sprint 1 | C13: Auth | D13: auth-service: login, refresh, logout, me; bcrypt; khóa 5 phút sau 5 lần sai; login_histories | E13: Nhật | F13: 2 | G13: 2 | H13: 10 | I13: P0 | J13: common | K13: API Auth P0 | L13: Chưa bắt đầu
A14: T10 | B14: Sprint 1 | C14: Inventory | D14: inventory-service: CRUD kho, đổi trạng thái kho + kiểm tra điều kiện ngừng hoạt động, kho mặc định, ngưỡng tồn theo kho | E14: Quân | F14: 2 | G14: 2 | H14: 10 | I14: P0 | J14: schema | K14: API Warehouses | L14: Chưa bắt đầu
A15: T11 | B15: Sprint 1 | C15: UI/UX | D15: Sitemap + user flow theo 5 vai trò (Figma/FigJam) | E15: Nghĩa | F15: 1 | G15: 1 | H15: 6 | I15: P0 | J15: SRS | K15: Sitemap, user flow | L15: Chưa bắt đầu
A16: T12 | B16: Sprint 1 | C16: UI/UX | D16: Wireframe low-fi toàn bộ màn hình (sheet Figma UX-UI) | E16: Nghĩa | F16: 1 | G16: 1 | H16: 10 | I16: P0 | J16: Sitemap | K16: Wireframe | L16: Chưa bắt đầu
A17: T13 | B17: Sprint 1 | C17: UI/UX | D17: Design system Figma: màu, typography, spacing, icon, component (button, input, select, table, tag trạng thái, modal, toast), light/dark, màu nhận diện kho | E17: Nghĩa | F17: 2 | G17: 2 | H17: 10 | I17: P0 | J17: Wireframe | K17: Figma library | L17: Chưa bắt đầu
A18: T14 | B18: Sprint 1 | C18: UI/UX | D18: Hi-fi: Đăng nhập, Quên MK (OTP), Layout chung (header chọn kho + chuông), Dashboard | E18: Nghĩa | F18: 2 | G18: 2 | H18: 6 | I18: P0 | J18: Design system | K18: Hi-fi nhóm 1 | L18: Chưa bắt đầu
A19: T15 | B19: Sprint 1 | C19: Frontend | D19: Setup React Vite: router, theme AntD từ token Figma, axios interceptor (refresh token, X-Warehouse-Id), Zustand, TanStack Query, MainLayout | E19: Nghĩa | F19: 2 | G19: 2 | H19: 6 | I19: P0 | K19: Khung app | L19: Chưa bắt đầu
A20: T16 | B20: Sprint 1 | C20: Quản lý | D20: Demo Sprint 1, retro, release v0.1.0 | E20: Cả nhóm | F20: 2 | G20: 2 | H20: 2 | I20: P1 | K20: Tag v0.1.0 | L20: Chưa bắt đầu
A21: T17 | B21: Sprint 2 | C21: Auth | D21: Quên mật khẩu OTP qua email (nodemailer/MailHog), đổi mật khẩu | E21: Nhật | F21: 3 | G21: 3 | H21: 6 | I21: P0 | J21: Auth P0 | K21: API OTP | L21: Chưa bắt đầu
A22: T18 | B22: Sprint 2 | C22: Auth | D22: Quản lý người dùng: CRUD, vô hiệu hóa, gán vai trò, gán kho (can_write), kho mặc định; system_settings; thống kê truy cập tháng | E22: Nhật | F22: 3 | G22: 3 | H22: 8 | I22: P0 | J22: Warehouses | K22: API Users | L22: Chưa bắt đầu
A23: T19 | B23: Sprint 2 | C23: Catalog | D23: catalog-service: CRUD nhóm SP, sản phẩm (tìm/lọc/sắp xếp/phân trang, xóa mềm), NCC (mã hóa STK), khách hàng; upload ảnh; API nội bộ lấy theo danh sách ID | E23: Nhật | F23: 3 | G23: 4 | H23: 14 | I23: P0 | J23: common | K23: API Catalog | L23: Chưa bắt đầu
A24: T20 | B24: Sprint 2 | C24: Inventory | D24: Lõi tồn kho: stock_balances, stock_items, stock_movements; API nội bộ receive/check/reserve/commit/release với transaction + SELECT FOR UPDATE + version + Redis lock + Idempotency-Key | E24: Quân | F24: 3 | G24: 4 | H24: 18 | I24: P0 | J24: schema | K24: Internal stock API | L24: Chưa bắt đầu
A25: T21 | B25: Sprint 2 | C25: Inventory | D25: Test đồng thời (2 request cùng serial → 1 thành công) – kịch bản 8.5#5 | E25: Quân | F25: 4 | G25: 4 | H25: 4 | I25: P0 | J25: Lõi tồn | K25: Jest test | L25: Chưa bắt đầu
A26: T22 | B26: Sprint 2 | C26: Order | D26: order-service: doc_sequences sinh mã, phiếu nhập CRUD + xác nhận → cộng tồn kho nhận, kiểm serial trùng toàn hệ thống, outbox publisher | E26: Quân | F26: 4 | G26: 4 | H26: 10 | I26: P0 | J26: Lõi tồn | K26: API Receipts | L26: Chưa bắt đầu
A27: T23 | B27: Sprint 2 | C27: Inventory | D27: API tra cứu tồn: theo SP ở mọi kho, theo kho, theo serial, hàng dưới ngưỡng, lịch sử biến động | E27: Quân | F27: 3 | G27: 3 | H27: 6 | I27: P0 | J27: Lõi tồn | K27: API Stock | L27: Chưa bắt đầu
A28: T24 | B28: Sprint 2 | C28: Report | D28: report-service khung: consumer RabbitMQ, audit log, notifications API + Socket.IO qua gateway | E28: Nhật | F28: 4 | G28: 4 | H28: 8 | I28: P1 | J28: RabbitMQ | K28: API Notifications | L28: Chưa bắt đầu
A29: T25 | B29: Sprint 2 | C29: UI/UX | D29: Hi-fi: Sản phẩm, Nhóm SP, NCC, Khách hàng, Danh mục kho, Người dùng & gán kho, Cấu hình | E29: Nghĩa | F29: 3 | G29: 3 | H29: 8 | I29: P0 | J29: Design system | K29: Hi-fi nhóm 2 | L29: Chưa bắt đầu
A30: T26 | B30: Sprint 2 | C30: UI/UX | D30: Hi-fi: Nhập kho, Xuất kho (bảng tồn kho khác), Giữ hàng, Chuyển kho (đi/đến/nhận/sai lệch), Thuê/mượn + trả, Đổi trả, Kiểm kê, Báo cáo, Thông báo, Nhật ký | E30: Nghĩa | F30: 3 | G30: 4 | H30: 14 | I30: P0 | J30: Design system | K30: Hi-fi nhóm 3 | L30: Chưa bắt đầu
A31: T27 | B31: Sprint 2 | C31: UI/UX | D31: Bản mobile/tablet cho màn chính, prototype click-through, review với nhóm | E31: Nghĩa | F31: 4 | G31: 4 | H31: 6 | I31: P1 | J31: Hi-fi | K31: Prototype | L31: Chưa bắt đầu
A32: T28 | B32: Sprint 2 | C32: Frontend | D32: Đăng nhập, quên MK OTP, ProtectedRoute, RoleGuard, bộ chọn kho đang làm việc, đổi theme sáng/tối | E32: Nghĩa | F32: 3 | G32: 3 | H32: 6 | I32: P0 | J32: API Auth | K32: Màn Auth | L32: Chưa bắt đầu
A33: T29 | B33: Sprint 2 | C33: Frontend | D33: Màn Sản phẩm (danh sách, form, mở rộng tồn theo kho), Nhóm SP, NCC, Khách hàng | E33: Nghĩa | F33: 4 | G33: 4 | H33: 8 | I33: P0 | J33: API Catalog | K33: Màn Danh mục | L33: Chưa bắt đầu
A34: T30 | B34: Sprint 2 | C34: Quản lý | D34: Demo Sprint 2, retro, release v0.2.0 | E34: Cả nhóm | F34: 4 | G34: 4 | H34: 2 | I34: P1 | K34: Tag v0.2.0 | L34: Chưa bắt đầu
A35: T31 | B35: Sprint 3 | C35: Order | D35: Phiếu xuất: CRUD, kiểm tồn khả dụng, gợi ý kho khác, tách phiếu theo kho, xác nhận/xuất (commit tồn), hủy, in PDF | E35: Quân | F35: 5 | G35: 5 | H35: 14 | I35: P0 | J35: Internal stock API | K35: API Export slips | L35: Chưa bắt đầu
A36: T32 | B36: Sprint 3 | C36: Inventory | D36: Giữ hàng (hold): tạo/nhả/gia hạn, hiển thị ai giữ cho ai, cron tự nhả khi hết hạn | E36: Quân | F36: 5 | G36: 5 | H36: 6 | I36: P0 | J36: Lõi tồn | K36: API Holds | L36: Chưa bắt đầu
A37: T33 | B37: Sprint 3 | C37: Order | D37: Phiếu chuyển kho: 8 trạng thái, gửi duyệt giữ hàng, duyệt/từ chối, xuất (IN_TRANSIT), nhận (khớp serial, nhận một phần), biên bản sai lệch + 3 cách xử lý, bỏ qua duyệt theo ngưỡng, in biên bản | E37: Quân | F37: 6 | G37: 6 | H37: 16 | I37: P0 | J37: Holds | K37: API Transfers | L37: Chưa bắt đầu
A38: T34 | B38: Sprint 3 | C38: Order | D38: Thanh toán & công nợ: ghi nhận thanh toán, trừ tiền cọc, danh sách công nợ, quá hạn 30 ngày; tra cứu bảo hành theo serial/mã SP | E38: Nhật | F38: 5 | G38: 5 | H38: 10 | I38: P0 | J38: Export slips | K38: API Payments/Debts | L38: Chưa bắt đầu
A39: T35 | B39: Sprint 3 | C39: Report | D39: Cảnh báo: cron + event (tồn dưới ngưỡng, sắp hết hạn thuê/mượn, phiếu chờ duyệt lâu, chuyển kho quá hạn/sai lệch, giữ hàng sắp hết hạn, công nợ quá hạn) theo phạm vi kho | E39: Nhật | F39: 5 | G39: 6 | H39: 10 | I39: P0 | J39: Notifications | K39: Cảnh báo realtime | L39: Chưa bắt đầu
A40: T36 | B40: Sprint 3 | C40: Report | D40: Read model báo cáo: consumer fact_sales, fact_stock_movements; job snapshot tồn cuối ngày | E40: Nhật | F40: 6 | G40: 6 | H40: 8 | I40: P0 | J40: Events | K40: report_db có dữ liệu | L40: Chưa bắt đầu
...

Sheet Tổng hợp khối lượng
A1: TỔNG HỢP KHỐI LƯỢNG THEO NGƯỜI & TUẦN
A2: Tự tính từ sheet 'Kế hoạch & Chia việc'. Giờ của task trải nhiều tuần được chia đều cho các tuần. Việc 'Cả nhóm' tính cho mỗi người.
A4: Người | B4: W1 | C4: W2 | D4: W3 | E4: W4 | F4: W5 | G4: W6 | H4: W7 | I4: W8 | J4: W9 | K4: Tổng giờ | L4: Số task | M4: Hoàn thành | N4: % hoàn thành
A5: Nhật | B5: =SUMPRODUCT((('Kế hoạch & Chia việc'!$E$5:$E$58="Nhật")+('Kế hoạch & Chia việc'!$E$5:$E$58="Cả nhóm"))*('Kế hoạch & Chia việc'!$F$5:$F$58<=1)*('Kế hoạch & Chia việc'!$G$5:$G$58>=1)*'Kế hoạch & Chia việc'!$H$5:$H$58/('Kế hoạch & Chia việc'!$G$5:$G$58-'Kế hoạch & Chia việc'!$F$5:$F$58+1)) -> 24 | C5: =SUMPRODUCT((('Kế hoạch & Chia việc'!$E$5:$E$58="Nhật")+('Kế hoạch & Chia việc'!$E$5:$E$58="Cả nhóm"))*('Kế hoạch & Chia việc'!$F$5:$F$58<=2)*('Kế hoạch & Chia việc'!$G$5:$G$58>=2)*'Kế hoạch & Chia việc'!$H$5:$H$58/('Kế hoạch & Chia việc'!$G$5:$G$58-'Kế hoạch & Chia việc'!$F$5:$F$58+1)) -> 30 | D5: =SUMPRODUCT((('Kế hoạch & Chia việc'!$E$5:$E$58="Nhật")+('Kế hoạch & Chia việc'!$E$5:$E$58="Cả nhóm"))*('Kế hoạch & Chia việc'!$F$5:$F$58<=3)*('Kế hoạch & Chia việc'!$G$5:$G$58>=3)*'Kế hoạch & Chia việc'!$H$5:$H$58/('Kế hoạch & Chia việc'!$G$5:$G$58-'Kế hoạch & Chia việc'!$F$5:$F$58+1)) -> 21 | E5: =SUMPRODUCT((('Kế hoạch & Chia việc'!$E$5:$E$58="Nhật")+('Kế hoạch & Chia việc'!$E$5:$E$58="Cả nhóm"))*('Kế hoạch & Chia việc'!$F$5:$F$58<=4)*('Kế hoạch & Chia việc'!$G$5:$G$58>=4)*'Kế hoạch & Chia việc'!$H$5:$H$58/('Kế hoạch & Chia việc'!$G$5:$G$58-'Kế hoạch & Chia việc'!$F$5:$F$58+1)) -> 17 | F5: =SUMPRODUCT((('Kế hoạch & Chia việc'!$E$5:$E$58="Nhật")+('Kế hoạch & Chia việc'!$E$5:$E$58="Cả nhóm"))*('Kế hoạch & Chia việc'!$F$5:$F$58<=5)*('Kế hoạch & Chia việc'!$G$5:$G$58>=5)*'Kế hoạch & Chia việc'!$H$5:$H$58/('Kế hoạch & Chia việc'!$G$5:$G$58-'Kế hoạch & Chia việc'!$F$5:$F$58+1)) -> 15 | G5: =SUMPRODUCT((('Kế hoạch & Chia việc'!$E$5:$E$58="Nhật")+('Kế hoạch & Chia việc'!$E$5:$E$58="Cả nhóm"))*('Kế hoạch & Chia việc'!$F$5:$F$58<=6)*('Kế hoạch & Chia việc'!$G$5:$G$58>=6)*'Kế hoạch & Chia việc'!$H$5:$H$58/('Kế hoạch & Chia việc'!$G$5:$G$58-'Kế hoạch & Chia việc'!$F$5:$F$58+1)) -> 15 | H5: =SUMPRODUCT((('Kế hoạch & Chia việc'!$E$5:$E$58="Nhật")+('Kế hoạch & Chia việc'!$E$5:$E$58="Cả nhóm"))*('Kế hoạch & Chia việc'!$F$5:$F$58<=7)*('Kế hoạch & Chia việc'!$G$5:$G$58>=7)*'Kế hoạch & Chia việc'!$H$5:$H$58/('Kế hoạch & Chia việc'!$G$5:$G$58-'Kế hoạch & Chia việc'!$F$5:$F$58+1)) -> 14 | I5: =SUMPRODUCT((('Kế hoạch & Chia việc'!$E$5:$E$58="Nhật")+('Kế hoạch & Chia việc'!$E$5:$E$58="Cả nhóm"))*('Kế hoạch & Chia việc'!$F$5:$F$58<=8)*('Kế hoạch & Chia việc'!$G$5:$G$58>=8)*'Kế hoạch & Chia việc'!$H$5:$H$58/('Kế hoạch & Chia việc'!$G$5:$G$58-'Kế hoạch & Chia việc'!$F$5:$F$58+1)) -> 16 | J5: =SUMPRODUCT((('Kế hoạch & Chia việc'!$E$5:$E$58="Nhật")+('Kế hoạch & Chia việc'!$E$5:$E$58="Cả nhóm"))*('Kế hoạch & Chia việc'!$F$5:$F$58<=9)*('Kế hoạch & Chia việc'!$G$5:$G$58>=9)*'Kế hoạch & Chia việc'!$H$5:$H$58/('Kế hoạch & Chia việc'!$G$5:$G$58-'Kế hoạch & Chia việc'!$F$5:$F$58+1)) -> 28 | K5: =SUM(B5:J5) -> 180 | L5: =COUNTIF('Kế hoạch & Chia việc'!$E$5:$E$58,"Nhật")+COUNTIF('Kế hoạch & Chia việc'!$E$5:$E$58,"Cả nhóm") -> 24 | M5: =COUNTIFS('Kế hoạch & Chia việc'!$E$5:$E$58,"Nhật",'Kế hoạch & Chia việc'!$L$5:$L$58,"Hoàn thành")+COUNTIFS('Kế hoạch & Chia việc'!$E$5:$E$58,"Cả nhóm",'Kế hoạch & Chia việc'!$L$5:$L$58,"Hoàn thành") -> 0 | N5: =IF(L5=0,0,M5/L5) -> 0
A6: Quân | B6: =SUMPRODUCT((('Kế hoạch & Chia việc'!$E$5:$E$58="Quân")+('Kế hoạch & Chia việc'!$E$5:$E$58="Cả nhóm"))*('Kế hoạch & Chia việc'!$F$5:$F$58<=1)*('Kế hoạch & Chia việc'!$G$5:$G$58>=1)*'Kế hoạch & Chia việc'!$H$5:$H$58/('Kế hoạch & Chia việc'!$G$5:$G$58-'Kế hoạch & Chia việc'!$F$5:$F$58+1)) -> 23 | C6: =SUMPRODUCT((('Kế hoạch & Chia việc'!$E$5:$E$58="Quân")+('Kế hoạch & Chia việc'!$E$5:$E$58="Cả nhóm"))*('Kế hoạch & Chia việc'!$F$5:$F$58<=2)*('Kế hoạch & Chia việc'!$G$5:$G$58>=2)*'Kế hoạch & Chia việc'!$H$5:$H$58/('Kế hoạch & Chia việc'!$G$5:$G$58-'Kế hoạch & Chia việc'!$F$5:$F$58+1)) -> 16 | D6: =SUMPRODUCT((('Kế hoạch & Chia việc'!$E$5:$E$58="Quân")+('Kế hoạch & Chia việc'!$E$5:$E$58="Cả nhóm"))*('Kế hoạch & Chia việc'!$F$5:$F$58<=3)*('Kế hoạch & Chia việc'!$G$5:$G$58>=3)*'Kế hoạch & Chia việc'!$H$5:$H$58/('Kế hoạch & Chia việc'!$G$5:$G$58-'Kế hoạch & Chia việc'!$F$5:$F$58+1)) -> 15 | E6: =SUMPRODUCT((('Kế hoạch & Chia việc'!$E$5:$E$58="Quân")+('Kế hoạch & Chia việc'!$E$5:$E$58="Cả nhóm"))*('Kế hoạch & Chia việc'!$F$5:$F$58<=4)*('Kế hoạch & Chia việc'!$G$5:$G$58>=4)*'Kế hoạch & Chia việc'!$H$5:$H$58/('Kế hoạch & Chia việc'!$G$5:$G$58-'Kế hoạch & Chia việc'!$F$5:$F$58+1)) -> 25 | F6: =SUMPRODUCT((('Kế hoạch & Chia việc'!$E$5:$E$58="Quân")+('Kế hoạch & Chia việc'!$E$5:$E$58="Cả nhóm"))*('Kế hoạch & Chia việc'!$F$5:$F$58<=5)*('Kế hoạch & Chia việc'!$G$5:$G$58>=5)*'Kế hoạch & Chia việc'!$H$5:$H$58/('Kế hoạch & Chia việc'!$G$5:$G$58-'Kế hoạch & Chia việc'!$F$5:$F$58+1)) -> 20 | G6: =SUMPRODUCT((('Kế hoạch & Chia việc'!$E$5:$E$58="Quân")+('Kế hoạch & Chia việc'!$E$5:$E$58="Cả nhóm"))*('Kế hoạch & Chia việc'!$F$5:$F$58<=6)*('Kế hoạch & Chia việc'!$G$5:$G$58>=6)*'Kế hoạch & Chia việc'!$H$5:$H$58/('Kế hoạch & Chia việc'!$G$5:$G$58-'Kế hoạch & Chia việc'!$F$5:$F$58+1)) -> 18 | H6: =SUMPRODUCT((('Kế hoạch & Chia việc'!$E$5:$E$58="Quân")+('Kế hoạch & Chia việc'!$E$5:$E$58="Cả nhóm"))*('Kế hoạch & Chia việc'!$F$5:$F$58<=7)*('Kế hoạch & Chia việc'!$G$5:$G$58>=7)*'Kế hoạch & Chia việc'!$H$5:$H$58/('Kế hoạch & Chia việc'!$G$5:$G$58-'Kế hoạch & Chia việc'!$F$5:$F$58+1)) -> 20 | I6: =SUMPRODUCT((('Kế hoạch & Chia việc'!$E$5:$E$58="Quân")+('Kế hoạch & Chia việc'!$E$5:$E$58="Cả nhóm"))*('Kế hoạch & Chia việc'!$F$5:$F$58<=8)*('Kế hoạch & Chia việc'!$G$5:$G$58>=8)*'Kế hoạch & Chia việc'!$H$5:$H$58/('Kế hoạch & Chia việc'!$G$5:$G$58-'Kế hoạch & Chia việc'!$F$5:$F$58+1)) -> 20 | J6: =SUMPRODUCT((('Kế hoạch & Chia việc'!$E$5:$E$58="Quân")+('Kế hoạch & Chia việc'!$E$5:$E$58="Cả nhóm"))*('Kế hoạch & Chia việc'!$F$5:$F$58<=9)*('Kế hoạch & Chia việc'!$G$5:$G$58>=9)*'Kế hoạch & Chia việc'!$H$5:$H$58/('Kế hoạch & Chia việc'!$G$5:$G$58-'Kế hoạch & Chia việc'!$F$5:$F$58+1)) -> 22 | K6: =SUM(B6:J6) -> 179 | L6: =COUNTIF('Kế hoạch & Chia việc'!$E$5:$E$58,"Quân")+COUNTIF('Kế hoạch & Chia việc'!$E$5:$E$58,"Cả nhóm") -> 22 | M6: =COUNTIFS('Kế hoạch & Chia việc'!$E$5:$E$58,"Quân",'Kế hoạch & Chia việc'!$L$5:$L$58,"Hoàn thành")+COUNTIFS('Kế hoạch & Chia việc'!$E$5:$E$58,"Cả nhóm",'Kế hoạch & Chia việc'!$L$5:$L$58,"Hoàn thành") -> 0 | N6: =IF(L6=0,0,M6/L6) -> 0
A7: Nghĩa | B7: =SUMPRODUCT((('Kế hoạch & Chia việc'!$E$5:$E$58="Nghĩa")+('Kế hoạch & Chia việc'!$E$5:$E$58="Cả nhóm"))*('Kế hoạch & Chia việc'!$F$5:$F$58<=1)*('Kế hoạch & Chia việc'!$G$5:$G$58>=1)*'Kế hoạch & Chia việc'!$H$5:$H$58/('Kế hoạch & Chia việc'!$G$5:$G$58-'Kế hoạch & Chia việc'!$F$5:$F$58+1)) -> 24 | C7: =SUMPRODUCT((('Kế hoạch & Chia việc'!$E$5:$E$58="Nghĩa")+('Kế hoạch & Chia việc'!$E$5:$E$58="Cả nhóm"))*('Kế hoạch & Chia việc'!$F$5:$F$58<=2)*('Kế hoạch & Chia việc'!$G$5:$G$58>=2)*'Kế hoạch & Chia việc'!$H$5:$H$58/('Kế hoạch & Chia việc'!$G$5:$G$58-'Kế hoạch & Chia việc'!$F$5:$F$58+1)) -> 28 | D7: =SUMPRODUCT((('Kế hoạch & Chia việc'!$E$5:$E$58="Nghĩa")+('Kế hoạch & Chia việc'!$E$5:$E$58="Cả nhóm"))*('Kế hoạch & Chia việc'!$F$5:$F$58<=3)*('Kế hoạch & Chia việc'!$G$5:$G$58>=3)*'Kế hoạch & Chia việc'!$H$5:$H$58/('Kế hoạch & Chia việc'!$G$5:$G$58-'Kế hoạch & Chia việc'!$F$5:$F$58+1)) -> 21 | E7: =SUMPRODUCT((('Kế hoạch & Chia việc'!$E$5:$E$58="Nghĩa")+('Kế hoạch & Chia việc'!$E$5:$E$58="Cả nhóm"))*('Kế hoạch & Chia việc'!$F$5:$F$58<=4)*('Kế hoạch & Chia việc'!$G$5:$G$58>=4)*'Kế hoạch & Chia việc'!$H$5:$H$58/('Kế hoạch & Chia việc'!$G$5:$G$58-'Kế hoạch & Chia việc'!$F$5:$F$58+1)) -> 23 | F7: =SUMPRODUCT((('Kế hoạch & Chia việc'!$E$5:$E$58="Nghĩa")+('Kế hoạch & Chia việc'!$E$5:$E$58="Cả nhóm"))*('Kế hoạch & Chia việc'!$F$5:$F$58<=5)*('Kế hoạch & Chia việc'!$G$5:$G$58>=5)*'Kế hoạch & Chia việc'!$H$5:$H$58/('Kế hoạch & Chia việc'!$G$5:$G$58-'Kế hoạch & Chia việc'!$F$5:$F$58+1)) -> 14 | G7: =SUMPRODUCT((('Kế hoạch & Chia việc'!$E$5:$E$58="Nghĩa")+('Kế hoạch & Chia việc'!$E$5:$E$58="Cả nhóm"))*('Kế hoạch & Chia việc'!$F$5:$F$58<=6)*('Kế hoạch & Chia việc'!$G$5:$G$58>=6)*'Kế hoạch & Chia việc'!$H$5:$H$58/('Kế hoạch & Chia việc'!$G$5:$G$58-'Kế hoạch & Chia việc'!$F$5:$F$58+1)) -> 14 | H7: =SUMPRODUCT((('Kế hoạch & Chia việc'!$E$5:$E$58="Nghĩa")+('Kế hoạch & Chia việc'!$E$5:$E$58="Cả nhóm"))*('Kế hoạch & Chia việc'!$F$5:$F$58<=7)*('Kế hoạch & Chia việc'!$G$5:$G$58>=7)*'Kế hoạch & Chia việc'!$H$5:$H$58/('Kế hoạch & Chia việc'!$G$5:$G$58-'Kế hoạch & Chia việc'!$F$5:$F$58+1)) -> 14 | I7: =SUMPRODUCT((('Kế hoạch & Chia việc'!$E$5:$E$58="Nghĩa")+('Kế hoạch & Chia việc'!$E$5:$E$58="Cả nhóm"))*('Kế hoạch & Chia việc'!$F$5:$F$58<=8)*('Kế hoạch & Chia việc'!$G$5:$G$58>=8)*'Kế hoạch & Chia việc'!$H$5:$H$58/('Kế hoạch & Chia việc'!$G$5:$G$58-'Kế hoạch & Chia việc'!$F$5:$F$58+1)) -> 18 | J7: =SUMPRODUCT((('Kế hoạch & Chia việc'!$E$5:$E$58="Nghĩa")+('Kế hoạch & Chia việc'!$E$5:$E$58="Cả nhóm"))*('Kế hoạch & Chia việc'!$F$5:$F$58<=9)*('Kế hoạch & Chia việc'!$G$5:$G$58>=9)*'Kế hoạch & Chia việc'!$H$5:$H$58/('Kế hoạch & Chia việc'!$G$5:$G$58-'Kế hoạch & Chia việc'!$F$5:$F$58+1)) -> 28 | K7: =SUM(B7:J7) -> 184 | L7: =COUNTIF('Kế hoạch & Chia việc'!$E$5:$E$58,"Nghĩa")+COUNTIF('Kế hoạch & Chia việc'!$E$5:$E$58,"Cả nhóm") -> 24 | M7: =COUNTIFS('Kế hoạch & Chia việc'!$E$5:$E$58,"Nghĩa",'Kế hoạch & Chia việc'!$L$5:$L$58,"Hoàn thành")+COUNTIFS('Kế hoạch & Chia việc'!$E$5:$E$58,"Cả nhóm",'Kế hoạch & Chia việc'!$L$5:$L$58,"Hoàn thành") -> 0 | N7: =IF(L7=0,0,M7/L7) -> 0
A8: Tổng nhóm | B8: =SUM(B5:B7) -> 71 | C8: =SUM(C5:C7) -> 74 | D8: =SUM(D5:D7) -> 57 | E8: =SUM(E5:E7) -> 65 | F8: =SUM(F5:F7) -> 49 | G8: =SUM(G5:G7) -> 47 | H8: =SUM(H5:H7) -> 48 | I8: =SUM(I5:I7) -> 54 | ... M8: =SUM(M5:M7) -> 0 | N8: =IF(L8=0,0,M8/L8) -> 0
A10: Ghi chú: khối lượng mục tiêu ~18–25 giờ/người/tuần (sinh viên vừa học vừa làm). Tuần vượt 25 giờ nên dời bớt task hoặc nhờ người khác hỗ trợ.

Sheet API - Nhật
A1: API DO NHẬT THỰC HIỆN (76 endpoint)
A2: Phạm vi: gateway · auth-service · catalog-service · report-service · thanh toán/công nợ/bảo hành (order-service). Sắp theo tuần. Gọi qua gateway http://localhost:8080. /internal/* chỉ gọi giữa các service (header X-Internal-Key). Header X-Warehouse-Id = kho đang làm việc.
A4: # | B4: Service | C4: Module | D4: Method | E4: Endpoint | F4: Mô tả | G4: Vai trò được gọi | H4: Tuần | I4: Ưu tiên | J4: SRS | K4: Trạng thái | L4: Ghi chú
A5: 1 | B5: auth-service | C5: Auth | D5: POST | E5: /api/v1/auth/login | F5: Đăng nhập username/email + mật khẩu; trả access + refresh token, kho mặc định, danh sách kho được gán; khóa 5 phút sau 5 lần sai | G5: Public | H5: W2 | I5: P0 | J5: 3.1.1 | K5: Chưa làm
A6: 2 | B6: auth-service | C6: Auth | D6: POST | E6: /api/v1/auth/refresh | F6: Cấp lại access token từ refresh token (rotate) | G6: Public | H6: W2 | I6: P0 | K6: Chưa làm
A7: 3 | B7: auth-service | C7: Auth | D7: POST | E7: /api/v1/auth/logout | F7: Thu hồi refresh token | G7: ALL | H7: W2 | I7: P0 | K7: Chưa làm
A8: 4 | B8: auth-service | C8: Auth | D8: GET | E8: /api/v1/auth/me | F8: Thông tin user hiện tại, vai trò, quyền, kho được gán | G8: ALL | H8: W2 | I8: P0 | K8: Chưa làm
A9: 5 | B9: auth-service | C9: Health | D9: GET | E9: /health | F9: Health check | G9: Public | H9: W2 | I9: P0 | K9: Chưa làm
A10: 6 | B10: auth-service | C10: Internal | D10: GET | E10: /internal/users/:id/scope | F10: Phạm vi kho + quyền của user (cho service khác) | G10: Internal | H10: W2 | I10: P0 | K10: Chưa làm
A11: 7 | B11: auth-service | C11: Auth | D11: PUT | E11: /api/v1/auth/me/default-warehouse | F11: Đổi kho mặc định / kho đang làm việc | G11: ALL | H11: W3 | I11: P1 | J11: 3.1.1 | K11: Chưa làm
A12: 8 | B12: auth-service | C12: Auth | D12: POST | E12: /api/v1/auth/forgot-password | F12: Gửi OTP về email | G12: Public | H12: W3 | I12: P0 | J12: 3.1.1 | K12: Chưa làm
A13: 9 | B13: auth-service | C13: Auth | D13: POST | E13: /api/v1/auth/verify-otp | F13: Xác thực OTP, trả reset token | G13: Public | H13: W3 | I13: P0 | K13: Chưa làm
A14: 10 | B14: auth-service | C14: Auth | D14: POST | E14: /api/v1/auth/reset-password | F14: Đặt lại mật khẩu bằng reset token | G14: Public | H14: W3 | I14: P0 | K14: Chưa làm
A15: 11 | B15: auth-service | C15: Auth | D15: PUT | E15: /api/v1/auth/change-password | F15: Đổi mật khẩu (cần mật khẩu cũ) | G15: ALL | H15: W3 | I15: P1 | K15: Chưa làm
A16: 12 | B16: auth-service | C16: Roles | D16: GET | E16: /api/v1/roles | F16: Danh sách vai trò & quyền | G16: ADMIN | H16: W3 | I16: P1 | K16: Chưa làm
A17: 13 | B17: auth-service | C17: Settings | D17: GET | E17: /api/v1/settings | F17: Đọc cấu hình hệ thống (số ngày giữ hàng, ngưỡng duyệt chuyển kho...) | G17: ADMIN, MANAGER | H17: W3 | I17: P1 | K17: Chưa làm
A18: 14 | B18: auth-service | C18: Settings | D18: PUT | E18: /api/v1/settings | F18: Cập nhật cấu hình | G18: ADMIN | H18: W3 | I18: P1 | K18: Chưa làm
A19: 15 | B19: auth-service | C19: Users | D19: GET | E19: /api/v1/users | F19: Danh sách người dùng (lọc vai trò, kho, trạng thái, tìm kiếm, phân trang) | G19: ADMIN | H19: W3 | I19: P0 | J19: 3.1.2 | K19: Chưa làm
A20: 16 | B20: auth-service | C20: Users | D20: POST | E20: /api/v1/users | F20: Tạo người dùng | G20: ADMIN | H20: W3 | I20: P0 | J20: 3.1.2 | K20: Chưa làm
A21: 17 | B21: auth-service | C21: Users | D21: GET | E21: /api/v1/users/:id | F21: Chi tiết người dùng + kho được gán | G21: ADMIN | H21: W3 | I21: P0 | K21: Chưa làm
A22: 18 | B22: auth-service | C22: Users | D22: PUT | E22: /api/v1/users/:id | F22: Cập nhật thông tin, vai trò | G22: ADMIN | H22: W3 | I22: P0 | K22: Chưa làm
A23: 19 | B23: auth-service | C23: Users | D23: PATCH | E23: /api/v1/users/:id/status | F23: Vô hiệu hóa / kích hoạt, mở khóa | G23: ADMIN | H23: W3 | I23: P0 | K23: Chưa làm
A24: 20 | B24: auth-service | C24: Users | D24: PUT | E24: /api/v1/users/:id/warehouses | F24: Gán danh sách kho + quyền ghi + kho mặc định | G24: ADMIN | H24: W3 | I24: P0 | J24: 3.10.3 | K24: Chưa làm
A25: 21 | B25: auth-service | C25: Users | D25: POST | E25: /api/v1/users/:id/reset-password | F25: Admin đặt lại mật khẩu | G25: ADMIN | H25: W3 | I25: P2 | K25: Chưa làm
A26: 22 | B26: auth-service | C26: Users | D26: GET | E26: /api/v1/users/stats/access | F26: Lượng truy cập theo tháng (từ login_histories) | G26: ADMIN | H26: W3 | I26: P2 | J26: 3.1.2 | K26: Chưa làm
A27: 23 | B27: catalog-service | C27: Health | D27: GET | E27: /health | F27: Health check | G27: Public | H27: W3 | I27: P0 | K27: Chưa làm
A28: 24 | B28: catalog-service | C28: Nhóm SP | D28: GET | E28: /api/v1/product-groups | F28: Danh sách nhóm sản phẩm (kèm số SP) | G28: ALL | H28: W3 | I28: P0 | J28: 6.1.2 | K28: Chưa làm
A29: 25 | B29: catalog-service | C29: Nhóm SP | D29: POST | E29: /api/v1/product-groups | F29: Tạo nhóm sản phẩm | G29: ADMIN, MANAGER | H29: W3 | I29: P0 | K29: Chưa làm
A30: 26 | B30: catalog-service | C30: Nhóm SP | D30: PUT | E30: /api/v1/product-groups/:id | F30: Sửa nhóm sản phẩm | G30: ADMIN, MANAGER | H30: W3 | I30: P0 | K30: Chưa làm
A31: 27 | B31: catalog-service | C31: Nhóm SP | D31: DELETE | E31: /api/v1/product-groups/:id | F31: Xóa mềm nhóm sản phẩm (chặn nếu còn SP) | G31: ADMIN, MANAGER | H31: W3 | I31: P1 | K31: Chưa làm
A32: 28 | B32: catalog-service | C32: Sản phẩm | D32: GET | E32: /api/v1/products | F32: Danh sách SP: tìm kiếm, lọc nhóm/giá/serial, sắp xếp, phân trang; ?includeStock=true gọi inventory lấy tồn | G32: ALL | H32: W3 | I32: P0 | J32: 3.2.1 | K32: Chưa làm
A33: 29 | B33: catalog-service | C33: Sản phẩm | D33: POST | E33: /api/v1/products | F33: Tạo sản phẩm | G33: ADMIN, MANAGER, STOREKEEPER | H33: W3 | I33: P0 | J33: 3.2.1 | K33: Chưa làm
A34: 30 | B34: catalog-service | C34: Sản phẩm | D34: GET | E34: /api/v1/products/:id | F34: Chi tiết sản phẩm | G34: ALL | H34: W3 | I34: P0 | K34: Chưa làm
A35: 31 | B35: catalog-service | C35: Sản phẩm | D35: PUT | E35: /api/v1/products/:id | F35: Sửa sản phẩm | G35: ADMIN, MANAGER, STOREKEEPER | H35: W3 | I35: P0 | K35: Chưa làm
A36: 32 | B36: catalog-service | C36: Sản phẩm | D36: DELETE | E36: /api/v1/products/:id | F36: Xóa mềm sản phẩm | G36: ADMIN, MANAGER | H36: W3 | I36: P0 | K36: Chưa làm
A37: 33 | B37: catalog-service | C37: Internal | D37: POST | E37: /internal/products/batch | F37: Lấy nhiều SP theo danh sách ID (snapshot cho chứng từ) | G37: Internal | H37: W4 | I37: P0 | K37: Chưa làm
A38: 34 | B38: catalog-service | C38: Internal | D38: POST | E38: /internal/partners/batch | F38: Lấy NCC/KH theo danh sách ID | G38: Internal | H38: W4 | I38: P0 | K38: Chưa làm
A39: 35 | B39: catalog-service | C39: Khách hàng | D39: GET | E39: /api/v1/customers | F39: Danh sách khách hàng (tìm theo tên/SĐT/MST) | G39: ALL | H39: W4 | I39: P0 | J39: 6.1.4 | K39: Chưa làm
A40: 36 | B40: catalog-service | C40: Khách hàng | D40: POST | E40: /api/v1/customers | F40: Tạo khách hàng | G40: ALL | H40: W4 | I40: P0 | K40: Chưa làm
A41: 37 | B41: catalog-service | C41: Khách hàng | D41: GET | E41: /api/v1/customers/:id | F41: Chi tiết khách hàng | G41: ALL | H41: W4 | I41: P0 | K41: Chưa làm
...

Sheet API - Quân
A1: API DO QUÂN THỰC HIỆN (81 endpoint)
A2: Phạm vi: inventory-service · order-service (nhập, xuất, thuê/mượn, đổi trả, chuyển kho). Sắp theo tuần. Gọi qua gateway http://localhost:8080. /internal/* chỉ gọi giữa các service (header X-Internal-Key). Header X-Warehouse-Id = kho đang làm việc.
A4: # | B4: Service | C4: Module | D4: Method | E4: Endpoint | F4: Mô tả | G4: Vai trò được gọi | H4: Tuần | I4: Ưu tiên | J4: SRS | K4: Trạng thái | L4: Ghi chú
A5: 1 | B5: inventory-service | C5: Health | D5: GET | E5: /health | F5: Health check | G5: Public | H5: W2 | I5: P0 | K5: Chưa làm
A6: 2 | B6: inventory-service | C6: Kho | D6: GET | E6: /api/v1/warehouses | F6: Danh sách kho (lọc loại, trạng thái; kèm tổng tồn, giá trị tồn) | G6: ALL | H6: W2 | I6: P0 | J6: 3.10.1 | K6: Chưa làm
A7: 3 | B7: inventory-service | C7: Kho | D7: POST | E7: /api/v1/warehouses | F7: Tạo kho (mã kho duy nhất) | G7: ADMIN | H7: W2 | I7: P0 | J7: UC-006 | K7: Chưa làm
A8: 4 | B8: inventory-service | C8: Kho | D8: GET | E8: /api/v1/warehouses/:id | F8: Chi tiết kho | G8: ALL | H8: W2 | I8: P0 | K8: Chưa làm
A9: 5 | B9: inventory-service | C9: Kho | D9: PUT | E9: /api/v1/warehouses/:id | F9: Sửa thông tin kho, thủ kho phụ trách, màu nhận diện | G9: ADMIN | H9: W2 | I9: P0 | K9: Chưa làm
A10: 6 | B10: inventory-service | C10: Kho | D10: GET | E10: /api/v1/warehouses/:id/close-check | F10: Kiểm tra điều kiện ngừng hoạt động (tồn, phiếu dở dang) – trả danh sách cần xử lý | G10: ADMIN | H10: W2 | I10: P0 | J10: 3.10.1 | K10: Chưa làm
A11: 7 | B11: inventory-service | C11: Kho | D11: PATCH | E11: /api/v1/warehouses/:id/status | F11: Đổi trạng thái ACTIVE/SUSPENDED/CLOSED | G11: ADMIN | H11: W2 | I11: P0 | J11: 8.5#8 | K11: Chưa làm
A12: 8 | B12: inventory-service | C12: Kho | D12: PATCH | E12: /api/v1/warehouses/:id/default | F12: Đặt kho mặc định hệ thống | G12: ADMIN | H12: W2 | I12: P1 | K12: Chưa làm
A13: 9 | B13: inventory-service | C13: Ngưỡng tồn | D13: GET | E13: /api/v1/warehouses/:id/min-stock | F13: Ngưỡng tồn tối thiểu theo SP tại kho | G13: ADMIN, MANAGER, STOREKEEPER | H13: W2 | I13: P1 | J13: 3.10.4 | K13: Chưa làm
A14: 10 | B14: inventory-service | C14: Ngưỡng tồn | D14: PUT | E14: /api/v1/warehouses/:id/min-stock | F14: Đặt ngưỡng tồn (bulk) | G14: ADMIN, MANAGER | H14: W2 | I14: P1 | K14: Chưa làm
A15: 11 | B15: inventory-service | C15: Internal | D15: POST | E15: /internal/stock/check | F15: Kiểm tồn khả dụng nhiều dòng + gợi ý kho khác | G15: Internal | H15: W3 | I15: P0 | J15: 3.4.1 | K15: Chưa làm
A16: 12 | B16: inventory-service | C16: Internal | D16: POST | E16: /internal/stock/receive | F16: Cộng tồn khi nhập/nhận trả (tạo stock_items cho serial) | G16: Internal | H16: W3 | I16: P0 | J16: 3.3.1 | K16: Chưa làm
A17: 13 | B17: inventory-service | C17: Internal | D17: POST | E17: /internal/stock/reserve | F17: Giữ hàng cho chứng từ (export/transfer/rental) | G17: Internal | H17: W3 | I17: P0 | K17: Chưa làm
A18: 14 | B18: inventory-service | C18: Internal | D18: POST | E18: /internal/stock/commit | F18: Trừ tồn thực theo hold (xuất, cho thuê, chuyển đi) | G18: Internal | H18: W3 | I18: P0 | J18: 3.10.7 | K18: Chưa làm
A19: 15 | B19: inventory-service | C19: Internal | D19: POST | E19: /internal/stock/release | F19: Nhả hold khi hủy/từ chối | G19: Internal | H19: W3 | I19: P0 | K19: Chưa làm
A20: 16 | B20: inventory-service | C20: Internal | D20: POST | E20: /internal/stock/reverse | F20: Ánh xạ ngược tồn khi sửa/hủy phiếu nhập | G20: Internal | H20: W4 | I20: P1 | J20: 3.3.1 | K20: Chưa làm
A21: 17 | B21: inventory-service | C21: Tồn kho | D21: GET | E21: /api/v1/stock | F21: Tồn theo (SP, kho): on_hand, hold, available, in_transit, rented, damaged; lọc kho/nhóm/dưới ngưỡng | G21: ALL | H21: W4 | I21: P0 | J21: 3.10.4 | K21: Chưa làm
A22: 18 | B22: inventory-service | C22: Tồn kho | D22: GET | E22: /api/v1/stock/products/:productId | F22: Tồn 1 SP ở tất cả kho (≤1s) | G22: ALL | H22: W4 | I22: P0 | J22: 4.1 | K22: Chưa làm
A23: 19 | B23: inventory-service | C23: Tồn kho | D23: GET | E23: /api/v1/stock/serials/:serial | F23: Tra cứu serial: kho hiện tại / đang chuyển / đang thuê / đã bán | G23: ALL | H23: W4 | I23: P0 | J23: 3.10.4 | K23: Chưa làm
A24: 20 | B24: inventory-service | C24: Tồn kho | D24: GET | E24: /api/v1/stock/items | F24: Danh sách đơn vị có serial theo kho/SP/trạng thái | G24: ALL | H24: W4 | I24: P0 | K24: Chưa làm
A25: 21 | B25: inventory-service | C25: Tồn kho | D25: GET | E25: /api/v1/stock/low | F25: Danh sách SP dưới ngưỡng theo kho và toàn hệ thống | G25: ALL | H25: W4 | I25: P0 | J25: 3.9 | K25: Chưa làm
A26: 22 | B26: inventory-service | C26: Tồn kho | D26: GET | E26: /api/v1/stock/movements | F26: Nhật ký biến động tồn (lọc kho, SP, loại, thời gian) | G26: ADMIN, MANAGER, ACCOUNTANT, STOREKEEPER | H26: W4 | I26: P0 | J26: 3.10.7 | K26: Chưa làm
A27: 23 | B27: order-service | C27: Health | D27: GET | E27: /health | F27: Health check | G27: Public | H27: W4 | I27: P0 | K27: Chưa làm
A28: 24 | B28: order-service | C28: Phiếu nhập | D28: GET | E28: /api/v1/goods-receipts | F28: Danh sách phiếu nhập (lọc kho, NCC, trạng thái, ngày) | G28: ADMIN, MANAGER, ACCOUNTANT, STOREKEEPER | H28: W4 | I28: P0 | J28: 3.3 | K28: Chưa làm
A29: 25 | B29: order-service | C29: Phiếu nhập | D29: POST | E29: /api/v1/goods-receipts | F29: Tạo phiếu nhập nháp (kho nhận bắt buộc, kiểm quyền kho) | G29: STOREKEEPER, MANAGER | H29: W4 | I29: P0 | J29: UC-001 | K29: Chưa làm
A30: 26 | B30: order-service | C30: Phiếu nhập | D30: GET | E30: /api/v1/goods-receipts/:id | F30: Chi tiết phiếu nhập | G30: ADMIN, MANAGER, ACCOUNTANT, STOREKEEPER | H30: W4 | I30: P0 | K30: Chưa làm
A31: 27 | B31: order-service | C31: Phiếu nhập | D31: PUT | E31: /api/v1/goods-receipts/:id | F31: Sửa phiếu (ánh xạ ngược tồn nếu đã xác nhận) | G31: STOREKEEPER, MANAGER | H31: W4 | I31: P0 | J31: 3.3.1 | K31: Chưa làm
A32: 28 | B32: order-service | C32: Phiếu nhập | D32: POST | E32: /api/v1/goods-receipts/:id/confirm | F32: Xác nhận → cộng tồn kho nhận, phát receipt.confirmed | G32: STOREKEEPER, MANAGER | H32: W4 | I32: P0 | J32: 8.5#1 | K32: Chưa làm
A33: 29 | B33: order-service | C33: Phiếu nhập | D33: POST | E33: /api/v1/goods-receipts/:id/cancel | F33: Hủy phiếu | G33: STOREKEEPER, MANAGER | H33: W4 | I33: P1 | K33: Chưa làm
A34: 30 | B34: order-service | C34: Phiếu nhập | D34: GET | E34: /api/v1/goods-receipts/:id/pdf | F34: In phiếu nhập PDF | G34: ALL | H34: W4 | I34: P1 | K34: Chưa làm
A35: 31 | B35: inventory-service | C35: Giữ hàng | D35: GET | E35: /api/v1/holds | F35: Danh sách giữ hàng (ai giữ, cho khách nào, đến khi nào) | G35: ALL | H35: W5 | I35: P0 | J35: 3.4.2 | K35: Chưa làm
A36: 32 | B36: inventory-service | C36: Giữ hàng | D36: POST | E36: /api/v1/holds | F36: Giữ hàng tại kho cho khách (trừ tồn khả dụng) | G36: SALES, STOREKEEPER, MANAGER | H36: W5 | I36: P0 | J36: 3.4.2 | K36: Chưa làm
A37: 33 | B37: inventory-service | C37: Giữ hàng | D37: PATCH | E37: /api/v1/holds/:id/extend | F37: Gia hạn giữ hàng | G37: SALES, MANAGER | H37: W5 | I37: P1 | K37: Chưa làm
A38: 34 | B38: inventory-service | C38: Giữ hàng | D38: DELETE | E38: /api/v1/holds/:id | F38: Nhả hàng đang giữ | G38: SALES, STOREKEEPER, MANAGER | H38: W5 | I38: P0 | K38: Chưa làm
A39: 35 | B39: inventory-service | C39: Tồn kho | D39: POST | E39: /api/v1/stock/damaged | F39: Đánh dấu hàng hư hỏng tại kho (chuyển sang qty_damaged) | G39: STOREKEEPER, MANAGER | H39: W5 | I39: P1 | J39: 2.3.6 | K39: Chưa làm
A40: 36 | B40: order-service | C40: Phiếu xuất | D40: GET | E40: /api/v1/export-slips | F40: Danh sách phiếu xuất (lọc kho, KH, trạng thái, loại, ngày) | G40: ALL | H40: W5 | I40: P0 | J40: 3.4 | K40: Chưa làm
A41: 37 | B41: order-service | C41: Phiếu xuất | D41: POST | E41: /api/v1/export-slips/check-availability | F41: Kiểm tồn khả dụng kho xuất + tồn các kho khác | G41: ALL | H41: W5 | I41: P0 | J41: UC-002 4a | K41: Chưa làm
...

Sheet API - Nghĩa (FE)
A1: API NGHĨA TÍCH HỢP Ở FRONTEND (141 endpoint)
A2: Không gồm /internal và /health. Tuần tích hợp = tuần backend xong + 1 (trước đó dùng mock MSW theo OpenAPI). Ghi màn hình sử dụng ở cột 'Màn hình'.
A4: # | B4: Module | C4: Method | D4: Endpoint | E4: Mô tả | F4: Backend làm | G4: Tuần BE xong | H4: Tuần tích hợp | I4: Ưu tiên | J4: Màn hình | K4: Trạng thái
A5: 1 | B5: Auth | C5: POST | D5: /api/v1/auth/login | E5: Đăng nhập username/email + mật khẩu; trả access + refresh token, kho mặc định, danh sách kho được gán; khóa 5 phút sau 5 lần sai | F5: Nhật | G5: W2 | H5: W3 | I5: P0 | K5: Chưa tích hợp
A6: 2 | B6: Auth | C6: POST | D6: /api/v1/auth/refresh | E6: Cấp lại access token từ refresh token (rotate) | F6: Nhật | G6: W2 | H6: W3 | I6: P0 | K6: Chưa tích hợp
A7: 3 | B7: Auth | C7: POST | D7: /api/v1/auth/logout | E7: Thu hồi refresh token | F7: Nhật | G7: W2 | H7: W3 | I7: P0 | K7: Chưa tích hợp
A8: 4 | B8: Auth | C8: GET | D8: /api/v1/auth/me | E8: Thông tin user hiện tại, vai trò, quyền, kho được gán | F8: Nhật | G8: W2 | H8: W3 | I8: P0 | K8: Chưa tích hợp
A9: 5 | B9: Kho | C9: GET | D9: /api/v1/warehouses | E9: Danh sách kho (lọc loại, trạng thái; kèm tổng tồn, giá trị tồn) | F9: Quân | G9: W2 | H9: W3 | I9: P0 | K9: Chưa tích hợp
A10: 6 | B10: Kho | C10: POST | D10: /api/v1/warehouses | E10: Tạo kho (mã kho duy nhất) | F10: Quân | G10: W2 | H10: W3 | I10: P0 | K10: Chưa tích hợp
A11: 7 | B11: Kho | C11: GET | D11: /api/v1/warehouses/:id | E11: Chi tiết kho | F11: Quân | G11: W2 | H11: W3 | I11: P0 | K11: Chưa tích hợp
A12: 8 | B12: Kho | C12: PUT | D12: /api/v1/warehouses/:id | E12: Sửa thông tin kho, thủ kho phụ trách, màu nhận diện | F12: Quân | G12: W2 | H12: W3 | I12: P0 | K12: Chưa tích hợp
A13: 9 | B13: Kho | C13: GET | D13: /api/v1/warehouses/:id/close-check | E13: Kiểm tra điều kiện ngừng hoạt động (tồn, phiếu dở dang) – trả danh sách cần xử lý | F13: Quân | G13: W2 | H13: W3 | I13: P0 | K13: Chưa tích hợp
A14: 10 | B14: Kho | C14: PATCH | D14: /api/v1/warehouses/:id/status | E14: Đổi trạng thái ACTIVE/SUSPENDED/CLOSED | F14: Quân | G14: W2 | H14: W3 | I14: P0 | K14: Chưa tích hợp
A15: 11 | B15: Kho | C15: PATCH | D15: /api/v1/warehouses/:id/default | E15: Đặt kho mặc định hệ thống | F15: Quân | G15: W2 | H15: W3 | I15: P1 | K15: Chưa tích hợp
A16: 12 | B16: Ngưỡng tồn | C16: GET | D16: /api/v1/warehouses/:id/min-stock | E16: Ngưỡng tồn tối thiểu theo SP tại kho | F16: Quân | G16: W2 | H16: W3 | I16: P1 | K16: Chưa tích hợp
... A145: 141 | B145: Xuất file | C145: GET | D145: /api/v1/reports/exports/:jobId/download | E145: Tải file | F145: Nhật | G145: W8 | H145: W9 | I145: P0 | K145: Chưa tích hợp

Sheet API - Tổng hợp
A1: TỔNG HỢP API THEO NGƯỜI
A2: Tự đếm từ các sheet API - Nhật / API - Quân / API - Nghĩa (FE).
A4: Người | B4: Sheet | C4: Số endpoint | D4: P0 | E4: Hoàn thành | F4: % hoàn thành
A5: Nhật | B5: API - Nhật | C5: =COUNTA('API - Nhật'!A5:A80) -> 76 | D5: =COUNTIF('API - Nhật'!I5:I80,"P0") -> 57 | E5: =COUNTIF('API - Nhật'!K5:K80,"Đã test") -> 0 | F5: =IF(C5=0,0,E5/C5) -> 0
A6: Quân | B6: API - Quân | C6: =COUNTA('API - Quân'!A5:A85) -> 81 | D6: =COUNTIF('API - Quân'!I5:I85,"P0") -> 64 | E6: =COUNTIF('API - Quân'!K5:K85,"Đã test") -> 0 | F6: =IF(C6=0,0,E6/C6) -> 0
A7: Nghĩa | B7: API - Nghĩa (FE) | C7: =COUNTA('API - Nghĩa (FE)'!A5:A145) -> 141 | D7: =COUNTIF('API - Nghĩa (FE)'!I5:I145,"P0") -> 106 | E7: =COUNTIF('API - Nghĩa (FE)'!K5:K145,"Đã test") -> 0 | F7: =IF(C7=0,0,E7/C7) -> 0
A9: Endpoint backend theo service
A10: Service | B10: Nhật | C10: Quân | D10: Tổng
A11: auth-service | B11: =COUNTIF('API - Nhật'!B5:B80,A11) -> 23 | C11: =COUNTIF('API - Quân'!B5:B85,A11) -> 0 | D11: =B11+C11 -> 23
A12: catalog-service | B12: =COUNTIF('API - Nhật'!B5:B80,A12) -> 25 | C12: =COUNTIF('API - Quân'!B5:B85,A12) -> 0 | D12: =B12+C12 -> 25
A13: inventory-service | B13: =COUNTIF('API - Nhật'!B5:B80,A13) -> 0 | C13: =COUNTIF('API - Quân'!B5:B85,A13) -> 38 | D13: =B13+C13 -> 38
A14: order-service | B14: =COUNTIF('API - Nhật'!B5:B80,A14) -> 6 | C14: =COUNTIF('API - Quân'!B5:B85,A14) -> 43 | D14: =B14+C14 -> 49
A15: report-service | B15: =COUNTIF('API - Nhật'!B5:B80,A15) -> 22 | C15: =COUNTIF('API - Quân'!B5:B85,A15) -> 0 | D15: =B15+C15 -> 22
A16: Tổng | B16: =SUM(B11:B15) -> 76 | C16: =SUM(C11:C15) -> 81 | D16: =SUM(D11:D15) -> 157
A18: Quy trình: backend đổi trạng thái sang 'Xong BE' khi merge vào develop, 'Đã test' khi có test. Nghĩa đổi sang 'Đã tích hợp' khi màn hình gọi API thật thay cho mock.

Sheet Database
A1: DATABASE THEO MICROSERVICE
A2: DDL đầy đủ: database/schema.sql · ERD: diagrams/02→06-erd-*.png. Không có khóa ngoại chéo database; chỉ lưu ID + snapshot.
A4: Service | B4: Database | C4: Bảng | D4: Mục đích | E4: Đối chiếu SRS TigerNet v1.1 | F4: Người phụ trách
A5: auth-service | B5: auth_db | C5: roles | D5: Vai trò (5 vai trò SRS), cờ all_warehouses | E5: Users.User_Role (SRS) → bảng | F5: Nhật
A6: auth-service | B6: auth_db | C6: permissions / role_permissions | D6: Quyền chi tiết theo vai trò | E6: Mới | F6: Nhật
A7: auth-service | B7: auth_db | C7: users | D7: Tài khoản, mật khẩu bcrypt, khóa đăng nhập, kho mặc định | E7: Users (SRS 6.1.1) | F7: Nhật
A8: auth-service | B8: auth_db | C8: user_warehouses | D8: Gán kho cho người dùng + quyền ghi | E8: User_Warehouses (6.1.10) | F8: Nhật
A9: auth-service | B9: auth_db | C9: refresh_tokens | D9: Refresh token đã băm, thu hồi | E9: Mới | F9: Nhật
A10: auth-service | B10: auth_db | C10: password_otps | D10: OTP quên mật khẩu | E10: Mới (3.1.1) | F10: Nhật
A11: auth-service | B11: auth_db | C11: login_histories | D11: Lịch sử đăng nhập, thống kê truy cập | E11: Mới (3.1.2) | F11: Nhật
A12: auth-service | B12: auth_db | C12: system_settings | D12: Cấu hình: số ngày giữ hàng, ngưỡng duyệt, ngày cảnh báo... | E12: Mới | F12: Nhật
A13: catalog-service | B13: catalog_db | C13: product_groups | D13: Nhóm sản phẩm | E13: Product_Groups (6.1.2) | F13: Nhật
A14: catalog-service | B14: catalog_db | C14: products | D14: Sản phẩm: mã, tên, ĐVT, giá, serial, bảo hành, ngưỡng chung | E14: Products (6.1.3) | F14: Nhật
A15: catalog-service | B15: catalog_db | C15: suppliers | D15: Nhà cung cấp, STK mã hóa | E15: Suppliers (6.1.5) | F15: Nhật
... A43: report-service | B43: report_db | C43: processed_events | D43: Chống xử lý event trùng | E43: Mới | F43: Nhật

Sheet Figma UX-UI
A1: THIẾT KẾ FIGMA UX/UI (Nghĩa phụ trách)
A2: Mỗi màn: bản desktop 1440 + trạng thái (trống, lỗi, loading). Dán link frame Figma vào cột 'Link Figma'. Figma hi-fi hoàn tất trước hết W4.
A4: # | B4: Nhóm | C4: Màn hình / Hạng mục | D4: Vai trò dùng | E4: Tuần thiết kế | F4: Tuần code | G4: Ưu tiên | H4: Link Figma | I4: Trạng thái Figma | J4: Trạng thái code
A5: 1 | B5: Nền tảng | C5: Sitemap + User flow 5 vai trò | D5: Tất cả | E5: W1 | F5: — | G5: P0 | I5: Chưa làm | J5: Chưa làm
A6: 2 | B6: Nền tảng | C6: Wireframe low-fi toàn bộ | D6: Tất cả | E6: W1 | F6: — | G6: P0 | I6: Chưa làm | J6: Chưa làm
A7: 3 | B7: Nền tảng | C7: Design system: color, type, spacing, icon, component, light/dark, màu kho | D7: Tất cả | E7: W2 | F7: W2 | G7: P0 | I7: Chưa làm | J7: Chưa làm
A8: 4 | B8: Xác thực | C8: Đăng nhập | D8: Tất cả | E8: W2 | F8: W3 | G8: P0 | I8: Chưa làm | J8: Chưa làm
A9: 5 | B9: Xác thực | C9: Quên mật khẩu (email → OTP → mật khẩu mới) | D9: Tất cả | E9: W2 | F9: W3 | G9: P0 | I9: Chưa làm | J9: Chưa làm
A10: 6 | B10: Layout | C10: Header (chọn kho đang làm việc, chuông cảnh báo, tài khoản) + Sidebar theo vai trò | D10: Tất cả | E10: W2 | F10: W2 | G10: P0 | I10: Chưa làm | J10: Chưa làm
A11: 7 | B11: Dashboard | C11: Dashboard (thẻ số liệu, biểu đồ nhập/xuất, hàng đang chuyển đến, cảnh báo) | D11: Tất cả | E11: W2 | F11: W8 | G11: P0 | I11: Chưa làm | J11: Chưa làm
A12: 8 | B12: Danh mục | C12: Sản phẩm: danh sách (mở rộng tồn theo kho), form, chi tiết | D12: Tất cả | E12: W3 | F12: W4 | G12: P0 | I12: Chưa làm | J12: Chưa làm
A13: 9 | B13: Danh mục | C13: Nhóm sản phẩm | D13: Admin, Quản lý | E13: W3 | F13: W4 | G13: P1 | I13: Chưa làm | J13: Chưa làm
A14: 10 | B14: Danh mục | C14: Nhà cung cấp: danh sách, form, lịch sử nhập | D14: Kế toán, Quản lý | E14: W3 | F14: W4 | G14: P0 | I14: Chưa làm | J14: Chưa làm
A15: 11 | B15: Danh mục | C15: Khách hàng: danh sách, form, công nợ | D15: Bán hàng, Kế toán | E15: W3 | F15: W4 | G15: P0 | I15: Chưa làm | J15: Chưa làm
A16: 12 | B16: Quản trị | C16: Danh mục kho: danh sách, form, tab người dùng được gán, ngừng hoạt động | D16: Admin | E16: W3 | F16: W5 | G16: P0 | I16: Chưa làm | J16: Chưa làm
... A32: 28 | B32: Trạng thái | C32: Empty state, loading skeleton, lỗi 403/404/500, mất kết nối | D32: Tất cả | E32: W4 | F32: W9 | G32: P1 | I32: Chưa làm | J32: Chưa làm

Sheet Git workflow
A1: GIT WORKFLOW
A2: Mô hình: Git Flow rút gọn (main + develop + feature) · Conventional Commits · Squash merge · Sơ đồ: diagrams/07-git-workflow.png
A4: 1. NHÁNH
A5: Nhánh | B5: Mục đích | C5: Quy tắc
A6: main | B6: Bản ổn định để demo / bàn giao | C6: Chỉ nhận merge từ release/* và hotfix/*; mỗi lần merge gắn tag vX.Y.Z; cấm push trực tiếp
A7: develop | B7: Nhánh tích hợp hằng ngày | C7: Nhận PR từ feature/*, fix/*; CI bắt buộc xanh + ≥1 approve; cấm push trực tiếp
A8: feature/<scope>-<mô-tả> | B8: Phát triển 1 task (1 issue) | C8: Tạo từ develop; vd feature/inventory-stock-hold, feature/fe-export-slip; sống ≤ 3 ngày
A9: fix/<scope>-<mô-tả> | B9: Sửa lỗi trên develop | C9: Tạo từ develop; vd fix/order-receipt-total
A10: release/vX.Y | B10: Chốt sprint | C10: Tạo từ develop cuối sprint; chỉ sửa bug; merge vào main (tag) và ngược lại develop
A11: hotfix/<mô-tả> | B11: Sửa gấp trên main | C11: Tạo từ main; merge vào main (tag patch) và develop
A13: 2. COMMIT (Conventional Commits)
A14: Loại | B14: Khi nào | C14: Ví dụ
A15: feat | B15: Thêm tính năng | C15: feat(order): tách phiếu xuất theo kho
A16: fix | B16: Sửa lỗi | C16: fix(inventory): không trừ tồn khi hold hết hạn
A17: refactor / perf | B17: Đổi cấu trúc / tối ưu, không đổi hành vi | C17: perf(report): thêm index fact_sales
A18: test | B18: Thêm/sửa test | C18: test(inventory): concurrent reserve same serial
A19: docs | B19: Tài liệu, OpenAPI | C19: docs(api): cập nhật transfers.yaml
A20: chore / ci / build | B20: Cấu hình, CI, docker, version | C20: ci: cache npm theo workspace
A21: Scope | B21: auth · catalog · inventory · order · report · gateway · common · fe · infra · docs | C21: Kiểm bằng commitlint + husky (commit-msg hook)
A23: 3. PULL REQUEST
A24: Bước | B24: Nội dung | C24: Ghi chú
A25: 1. Nhận task | B25: Kéo issue sang In progress, tạo nhánh từ develop mới nhất | C25: git switch develop && git pull && git switch -c feature/...
A26: 2. Code + test | B26: Commit nhỏ, đúng chuẩn; chạy npm run lint && npm test | C26: Đổi API → cập nhật OpenAPI trong cùng PR
A27: 3. Đồng bộ | B27: git fetch origin && git rebase origin/develop trước khi mở PR | C27: Chỉ rebase nhánh của mình
A28: 4. Mở PR → develop | B28: Tiêu đề theo commit convention; mô tả: làm gì, cách test, ảnh màn hình (FE), 'Closes #issue' | C28: PR < 400 dòng thay đổi
A29: 5. Review | B29: Nhật ↔ Quân review chéo; PR frontend: Nhật hoặc Quân review phần gọi API; PR đổi API contract: Nghĩa phải approve | C29: Phản hồi review trong 24h
A30: 6. Merge | B30: CI xanh + ≥1 approve → Squash and merge → xóa nhánh | C30: Issue tự đóng, card sang Done
A32: 4. LỊCH RELEASE
A33: Tag | B33: Ngày | C33: Nội dung
A34: v0.1.0 | B34: 08/11/2026 | C34: Sprint 1 – nền tảng, đăng nhập, kho
A35: v0.2.0 | B35: 22/11/2026 | C35: Sprint 2 – danh mục, người dùng, lõi tồn kho, phiếu nhập
A36: v0.3.0 | B36: 06/12/2026 | C36: Sprint 3 – xuất kho, giữ hàng, chuyển kho, công nợ, cảnh báo
A37: v0.4.0 | B37: 20/12/2026 | C37: Sprint 4 – thuê/mượn, đổi trả, kiểm kê, báo cáo (code freeze)
A38: v1.0.0 | B38: 25/12/2026 | C38: Bàn giao đồ án
A40: 5. CẤU HÌNH REPO
A41: Mục | B41: Thiết lập | C41: Ghi chú
A42: Branch protection | B42: main, develop: require PR, 1 approval, status checks (ci), no force push | C42: Settings → Branches
A43: CODEOWNERS | B43: services/auth-service, catalog-service, report-service, api-gateway, packages → Nhật; inventory-service, order-service, infra → Quân; frontend → Nghĩa | C43: Tự gán reviewer
A44: CI (GitHub Actions) | B44: Mỗi PR: npm ci → lint → test (MySQL/Redis service container) → build; chỉ chạy service bị thay đổi | C44: .github/workflows/ci.yml
A45: Bí mật | B45: Không commit .env; dùng .env.example; secret deploy lưu ở GitHub Secrets | C45: .gitignore
...
